[23/Jan/2017 14:23:29] "GET /favicon.ico HTTP/1.1" 500 59
Traceback (most recent call last):
  File "/usr/lib/python3/dist-packages/django/core/handlers/base.py", line 108, in get_response
    response = middleware_method(request)
  File "/usr/lib/python3/dist-packages/django/middleware/common.py", line 62, in process_request
    host = request.get_host()
  File "/usr/lib/python3/dist-packages/django/http/request.py", line 102, in get_host
    raise DisallowedHost(msg)
django.core.exceptions.DisallowedHost: Invalid HTTP_HOST header: '192.168.123.35:8000'. You may need to add '192.168.123.35' to ALLOWED_HOSTS.

During handling of the above exception, another exception occurred:

Traceback (most recent call last):
  File "/usr/lib/python3.5/wsgiref/handlers.py", line 137, in run
    self.result = application(self.environ, self.start_response)
  File "/usr/lib/python3/dist-packages/django/contrib/staticfiles/handlers.py", line 63, in __call__
    return self.application(environ, start_response)
  File "/usr/lib/python3/dist-packages/django/core/handlers/wsgi.py", line 189, in __call__
    response = self.get_response(request)
  File "/usr/lib/python3/dist-packages/django/core/handlers/base.py", line 207, in get_response
    return debug.technical_500_response(request, *sys.exc_info(), status_code=400)
  File "/usr/lib/python3/dist-packages/django/views/debug.py", line 97, in technical_500_response
    html = reporter.get_traceback_html()
  File "/usr/lib/python3/dist-packages/django/views/debug.py", line 384, in get_traceback_html
    return t.render(c)
  File "/usr/lib/python3/dist-packages/django/template/base.py", line 210, in render
    return self._render(context)
  File "/usr/lib/python3/dist-packages/django/template/base.py", line 202, in _render
    return self.nodelist.render(context)
  File "/usr/lib/python3/dist-packages/django/template/base.py", line 905, in render
    bit = self.render_node(node, context)
  File "/usr/lib/python3/dist-packages/django/template/debug.py", line 79, in render_node
    return node.render(context)
  File "/usr/lib/python3/dist-packages/django/template/defaulttags.py", line 329, in render
    return nodelist.render(context)
  File "/usr/lib/python3/dist-packages/django/template/base.py", line 905, in render
    bit = self.render_node(node, context)
  File "/usr/lib/python3/dist-packages/django/template/debug.py", line 79, in render_node
    return node.render(context)
  File "/usr/lib/python3/dist-packages/django/template/debug.py", line 89, in render
    output = self.filter_expression.resolve(context)
  File "/usr/lib/python3/dist-packages/django/template/base.py", line 648, in resolve
    obj = self.var.resolve(context)
  File "/usr/lib/python3/dist-packages/django/template/base.py", line 789, in resolve
    value = self._resolve_lookup(context)
  File "/usr/lib/python3/dist-packages/django/template/base.py", line 849, in _resolve_lookup
    current = current()
  File "/usr/lib/python3/dist-packages/django/http/request.py", line 152, in build_absolute_uri
    host=self.get_host(),
  File "/usr/lib/python3/dist-packages/django/http/request.py", line 102, in get_host
    raise DisallowedHost(msg)
django.core.exceptions.DisallowedHost: Invalid HTTP_HOST header: '192.168.123.35:8000'. You may need to add '192.168.123.35' to ALLOWED_HOSTS.
[23/Jan/2017 14:23:49] "GET /invest HTTP/1.1" 500 59
Traceback (most recent call last):
  File "/usr/lib/python3/dist-packages/django/core/handlers/base.py", line 108, in get_response
    response = middleware_method(request)
  File "/usr/lib/python3/dist-packages/django/middleware/common.py", line 62, in process_request
    host = request.get_host()
  File "/usr/lib/python3/dist-packages/django/http/request.py", line 102, in get_host
    raise DisallowedHost(msg)
django.core.exceptions.DisallowedHost: Invalid HTTP_HOST header: '192.168.123.35:8000'. You may need to add '192.168.123.35' to ALLOWED_HOSTS.

During handling of the above exception, another exception occurred:

Traceback (most recent call last):
  File "/usr/lib/python3.5/wsgiref/handlers.py", line 137, in run
    self.result = application(self.environ, self.start_response)
  File "/usr/lib/python3/dist-packages/django/contrib/staticfiles/handlers.py", line 63, in __call__
    return self.application(environ, start_response)
  File "/usr/lib/python3/dist-packages/django/core/handlers/wsgi.py", line 189, in __call__
    response = self.get_response(request)
  File "/usr/lib/python3/dist-packages/django/core/handlers/base.py", line 207, in get_response
    return debug.technical_500_response(request, *sys.exc_info(), status_code=400)
  File "/usr/lib/python3/dist-packages/django/views/debug.py", line 97, in technical_500_response
    html = reporter.get_traceback_html()
  File "/usr/lib/python3/dist-packages/django/views/debug.py", line 384, in get_traceback_html
    return t.render(c)
  File "/usr/lib/python3/dist-packages/django/template/base.py", line 210, in render
    return self._render(context)
  File "/usr/lib/python3/dist-packages/django/template/base.py", line 202, in _render
    return self.nodelist.render(context)
  File "/usr/lib/python3/dist-packages/django/template/base.py", line 905, in render
    bit = self.render_node(node, context)
  File "/usr/lib/python3/dist-packages/django/template/debug.py", line 79, in render_node
    return node.render(context)
  File "/usr/lib/python3/dist-packages/django/template/defaulttags.py", line 329, in render
    return nodelist.render(context)
  File "/usr/lib/python3/dist-packages/django/template/base.py", line 905, in render
    bit = self.render_node(node, context)
  File "/usr/lib/python3/dist-packages/django/template/debug.py", line 79, in render_node
    return node.render(context)
  File "/usr/lib/python3/dist-packages/django/template/debug.py", line 89, in render
    output = self.filter_expression.resolve(context)
  File "/usr/lib/python3/dist-packages/django/template/base.py", line 648, in resolve
    obj = self.var.resolve(context)
  File "/usr/lib/python3/dist-packages/django/template/base.py", line 789, in resolve
    value = self._resolve_lookup(context)
  File "/usr/lib/python3/dist-packages/django/template/base.py", line 849, in _resolve_lookup
    current = current()
  File "/usr/lib/python3/dist-packages/django/http/request.py", line 152, in build_absolute_uri
    host=self.get_host(),
  File "/usr/lib/python3/dist-packages/django/http/request.py", line 102, in get_host
    raise DisallowedHost(msg)
django.core.exceptions.DisallowedHost: Invalid HTTP_HOST header: '192.168.123.35:8000'. You may need to add '192.168.123.35' to ALLOWED_HOSTS.
[23/Jan/2017 14:23:49] "GET /favicon.ico HTTP/1.1" 500 59
Performing system checks...

January 23, 2017 - 14:23:21
Django version 1.8.7, using settings 'InvestmentsHelper.settings'
Starting development server at http://0.0.0.0:8000/
Quit the server with CONTROL-C.
